<robot name="fetch">

  <link name="root">
    <inertial>
      <mass value="0"/>
      <inertia ixx="0.00" ixy="0.00" ixz="0.00" iyy="0.00" iyz="0.00" izz="0.00"/>
    </inertial>
  </link>
  <link name="root_arm_1_link_1">
    <inertial>
      <mass value="0"/>
      <inertia ixx="0.00" ixy="0.00" ixz="0.00" iyy="0.00" iyz="0.00" izz="0.00"/>
    </inertial>
  </link>
  <link name="root_arm_1_link_2">
    <inertial>
      <mass value="0"/>
      <inertia ixx="0.00" ixy="0.00" ixz="0.00" iyy="0.00" iyz="0.00" izz="0.00"/>
    </inertial>
  </link>
  <joint name="root_x_axis_joint" type="prismatic">
    <parent link="root"/>
    <child link="root_arm_1_link_1"/>
    <axis xyz="1 0 0"/>
    <limit effort="100" lower="-20" upper="20" velocity="0.50"/>
    <dynamics damping="10.0" friction="10"/>
  </joint>
  <joint name="root_y_axis_joint" type="prismatic">
    <parent link="root_arm_1_link_1"/>
    <child link="root_arm_1_link_2"/>
    <axis xyz="0 1 0"/>
    <limit effort="100" lower="-20" upper="20" velocity="0.50"/>
    <dynamics damping="10.0" friction="10"/>
  </joint>
  <joint name="root_z_rotation_joint" type="continuous">
    <parent link="root_arm_1_link_2"/>
    <child link="base_link"/>
    <axis xyz="0 0 1"/>
    <dynamics damping="10.0" friction="1"/>
  </joint>

  <!-- <link name="base_link">
    <inertial>
      <origin rpy="0 0 0" xyz="-0.0036 0.0 0.0014"/>
      <mass value="70.1294"/>
      <inertia ixx="1.225" ixy="0.0099" ixz="0.0062" iyy="1.2853" iyz="-0.0034" izz="0.987"/>
    </inertial>
    <visual>
      <origin rpy="0 0 0" xyz="0 0 0"/>
      <geometry>
        <mesh filename="fetch_description/meshes/base_link.dae"/>
      </geometry>
    </visual>
    <collision>
      <origin rpy="0 0 0" xyz="0 0 0"/>
      <geometry>
        <mesh filename="fetch_description/meshes/base_link_collision.STL"/>
      </geometry>
    </collision>
  </link> -->
  <link name="base_link">
    <inertial>
        <origin rpy="0 0 0" xyz="0 0 0"/>
        <mass value="70.1294"/>
        <inertia ixx="1.225" ixy="0.0099" ixz="0.0062" iyy="1.2853" iyz="-0.0034" izz="0.987"/>
    </inertial>
    <visual>
        <origin rpy="0 0 0" xyz="0 0 0.1"/>
        <geometry>
            <box size="0.5 0.5 0.1"/> <!-- Replace dimensions with your desired size -->
        </geometry>
    </visual>
    <collision>
    <origin rpy="0 0 0" xyz="0 0 0.1"/>
    <geometry>
        <box size="0.5 0.5 0.1"/> <!-- Ensure this matches the visual box -->
    </geometry>
    </collision>
  </link>

  <link name="r_wheel_link">
    <inertial>
      <origin rpy="0 0 0" xyz="0 0 0"/>
      <mass value="4.3542"/>
      <inertia ixx="0.0045" ixy="0" ixz="0" iyy="0.005" iyz="0" izz="0.0045"/>
    </inertial>
    <visual>
      <origin rpy="0 0 0" xyz="0 0 0"/>
      <geometry>
        <mesh filename="fetch_description/meshes/r_wheel_link.STL"/>
      </geometry>
      <material name="">
        <color rgba="0.086 0.506 0.767 1"/>
      </material>
    </visual>
    <collision>
      <origin rpy="0 0 0" xyz="0 0 0"/>
      <geometry>
        <mesh filename="fetch_description/meshes/r_wheel_link_collision.STL"/>
      </geometry>
    </collision>
  </link>
  <joint name="r_wheel_joint" type="fixed">
    <origin rpy="-6.123E-17 0 0" xyz="0.0012914 -0.18738 0.055325"/>
    <parent link="base_link"/>
    <child link="r_wheel_link"/>
    <axis xyz="0 1 0"/>
    <limit effort="8.85" velocity="17.4"/>
  </joint>
  <link name="l_wheel_link">
    <inertial>
      <origin rpy="0 0 0" xyz="0 0 0"/>
      <mass value="4.3542"/>
      <inertia ixx="0.0045" ixy="0" ixz="0" iyy="0.005" iyz="0" izz="0.0045"/>
    </inertial>
    <visual>
      <origin rpy="0 0 0" xyz="0 0 0"/>
      <geometry>
        <mesh filename="fetch_description/meshes/l_wheel_link.STL"/>
      </geometry>
      <material name="">
        <color rgba="0.086 0.506 0.767 1"/>
      </material>
    </visual>
    <collision>
      <origin rpy="0 0 0" xyz="0 0 0"/>
      <geometry>
        <mesh filename="fetch_description/meshes/l_wheel_link_collision.STL"/>
      </geometry>
    </collision>
  </link>
  <joint name="l_wheel_joint" type="fixed">
    <origin rpy="-6.123E-17 0 0" xyz="0.0012914 0.18738 0.055325"/>
    <parent link="base_link"/>
    <child link="l_wheel_link"/>
    <axis xyz="0 1 0"/>
    <limit effort="8.85" velocity="17.4"/>
  </joint>

  <!-- Eye Joints/Links -->
    <link name="head_pan_link">
    <inertial>
      <origin rpy="0 0 0" xyz="0.0321 0.0161 0.0390"/>
      <mass value="2.2556"/>
      <inertia ixx="0.001" ixy="0.00" ixz="0.0007" iyy="0.001" iyz="-0.0" izz="0.001"/>
    </inertial>
    <visual>
      <origin rpy="0 0 0" xyz="0 0 0"/>
      <geometry>
        <mesh filename="fetch_description/meshes/head_pan_link.dae"/>
      </geometry>
    </visual>
    <collision>
      <origin rpy="0 0 0" xyz="0 0 0"/>
      <geometry>
        <mesh filename="fetch_description/meshes/head_pan_link_collision.STL"/>
      </geometry>
    </collision>
  </link>
  <joint name="head_pan_joint" type="revolute">
    <origin rpy="0 0 0" xyz="0.053125 0 0.603001417713939"/>
    <parent link="base_link"/>
    <child link="head_pan_link"/>
    <axis xyz="0 0 1"/>
    <limit effort="100" lower="-1.57" upper="1.57" velocity="14000"/>
  </joint>

    <link name="head_tilt_link">
    <inertial>
      <origin rpy="0 0 0" xyz="0.0081 0.0025 0.0113"/>
      <mass value="0.9087"/>
      <inertia ixx="0.001" ixy="-0.0" ixz="0.0" iyy="0.001" iyz="0.0000" izz="0.001"/>
    </inertial>
    <visual>
      <origin rpy="0 0 0" xyz="0 0 0"/>
      <geometry>
        <mesh filename="fetch_description/meshes/head_tilt_link.dae"/>
      </geometry>
    </visual>
    <collision>
      <origin rpy="0 0 0" xyz="0 0 0"/>
      <geometry>
        <mesh filename="fetch_description/meshes/head_tilt_link_collision.STL"/>
      </geometry>
    </collision>
  </link>
  <joint name="head_tilt_joint" type="revolute">
    <origin rpy="0 0 0" xyz="0.14253 0 0.057999"/>
    <parent link="head_pan_link"/>
    <child link="head_tilt_link"/>
    <axis xyz="0 1 0"/>
    <limit effort="100" lower="-1.57" upper="1.57" velocity="14000"/>
  </joint>

    <!-- Camera Links -->

  <link name="head_camera_link"/>
  <joint name="head_camera_joint" type="fixed">
    <origin rpy="0 0 0" xyz="0.055 0 0.0225"/>
    <parent link="head_tilt_link"/>
    <child link="head_camera_link"/>
  </joint>
  <link name="head_camera_rgb_frame"/>
  <joint name="head_camera_rgb_joint" type="fixed">
    <origin rpy="0 0 0" xyz="0 0.02 0"/>
    <parent link="head_camera_link"/>
    <child link="head_camera_rgb_frame"/>
  </joint>
  <link name="head_camera_rgb_optical_frame"/>
  <joint name="head_camera_rgb_optical_joint" type="fixed">
    <origin rpy="-1.57079632679 0 -1.57079632679" xyz="0 0 0"/>
    <parent link="head_camera_rgb_frame"/>
    <child link="head_camera_rgb_optical_frame"/>
  </joint>
  <!-- <link name="head_camera_depth_frame"/>
  <joint name="head_camera_depth_joint" type="fixed">
    <origin rpy="0 0 0" xyz="0 0.045 0"/>
    <parent link="head_camera_link"/>
    <child link="head_camera_depth_frame"/>
  </joint>
  <link name="head_camera_depth_optical_frame"/>
  <joint name="head_camera_depth_optical_joint" type="fixed">
    <origin rpy="-1.57079632679 0 -1.57079632679" xyz="0 0 0"/>
    <parent link="head_camera_depth_frame"/>
    <child link="head_camera_depth_optical_frame"/>
  </joint> -->
</robot>
